<?xml version="1.0" encoding="utf-8"?>
<!-- This URDF was automatically created by SolidWorks to URDF Exporter! Originally created by Stephen Brawner (brawner@gmail.com) 
     Commit Version: 1.6.0-4-g7f85cfe  Build Version: 1.6.7995.38578
     For more information, please see http://wiki.ros.org/sw_urdf_exporter -->
<robot
  name="mobilerobot">
  <link
    name="chassis">
    <inertial>
      <origin
        xyz="0.00797986677342635 -0.0266763382007091 0"
        rpy="0 0 0" />
      <mass
        value="2.81769672178167" />
      <inertia
        ixx="0.00541802256048597"
        ixy="0.000552734377907198"
        ixz="3.75109526218469E-19"
        iyy="0.0380041507942826"
        iyz="1.93268346595262E-19"
        izz="0.0340639115250186" />
    </inertial>
    <visual>
      <origin
        xyz="0 0 0"
        rpy="0 0 0" />
      <geometry>
        <mesh
          filename="/home/ankit/ros2_ws/src/lab7/meshes/chassis.STL"/>
      </geometry>
      <material
        name="">
        <color
          rgba="0.792156862745098 0.819607843137255 0.933333333333333 1" />
      </material>
    </visual>
    <collision>
      <origin
        xyz="0 0 0"
        rpy="0 0 0" />
      <geometry>
        <mesh
          filename="/home/ankit/ros2_ws/src/lab7/meshes/chassis.STL"/>
      </geometry>
    </collision>
  </link>
  <link
    name="leftwheel">
    <inertial>
      <origin
        xyz="0 0 0.0140027447392498"
        rpy="0 0 0" />
      <mass
        value="0.214610048148353" />
      <inertia
        ixx="0.000182772782515315"
        ixy="1.42466315810084E-36"
        ixz="-1.55674064615642E-37"
        iyy="0.000182772782515315"
        iyz="1.55997616305848E-20"
        izz="0.000289392838742408" />
    </inertial>
    <visual>
      <origin
        xyz="0 0 0"
        rpy="0 0 0" />
      <geometry>
        <mesh
          filename="/home/ankit/ros2_ws/src/lab7/meshes/leftwheel.STL"/>
      </geometry>
      <material
        name="">
        <color
          rgba="0.792156862745098 0.819607843137255 0.933333333333333 1" />
      </material>
    </visual>
    <collision>
      <origin
        xyz="0 0 0"
        rpy="0 0 0" />
      <geometry>
        <mesh
          filename="/home/ankit/ros2_ws/src/lab7/meshes/leftwheel.STL"/>
      </geometry>
    </collision>
  </link>
  <joint
    name="leftjoint"
    type="continuous">
    <origin
      xyz="-0.08 -0.025 -0.095"
      rpy="0 0 0" />
    <parent
      link="chassis" />
    <child
      link="leftwheel" />
    <axis
      xyz="0 0 -1" />
    <limit
      effort="1"
      velocity="1" />
  </joint>
  <link
    name="rightwheel">
    <inertial>
      <origin
        xyz="-1.38777878078145E-17 0 -0.0140027447392497"
        rpy="0 0 0" />
      <mass
        value="0.214610048148353" />
      <inertia
        ixx="0.000182772782515315"
        ixy="-3.37864678465993E-20"
        ixz="-1.8464010708929E-20"
        iyy="0.000182772782515315"
        iyz="7.82816381055348E-21"
        izz="0.000289392838742408" />
    </inertial>
    <visual>
      <origin
        xyz="0 0 0"
        rpy="0 0 0" />
      <geometry>
        <mesh
          filename="/home/ankit/ros2_ws/src/lab7/meshes/rightwheel.STL"/>
      </geometry>
      <material
        name="">
        <color
          rgba="0.792156862745098 0.819607843137255 0.933333333333333 1" />
      </material>
    </visual>
    <collision>
      <origin
        xyz="0 0 0"
        rpy="0 0 0" />
      <geometry>
        <mesh
          filename="/home/ankit/ros2_ws/src/lab7/meshes/rightwheel.STL"/>
      </geometry>
    </collision>
  </link>
  <joint
    name="rightjoint"
    type="continuous">
    <origin
      xyz="-0.08 -0.025 0.095"
      rpy="0 0 0" />
    <parent
      link="chassis" />
    <child
      link="rightwheel" />
    <axis
      xyz="0 0 -1" />
    <limit
      effort="1"
      velocity="1" />
  </joint>
</robot>